ERROR:discord.client:Attempting a reconnect in 1.61s
Traceback (most recent call last):
  File "/home/hukasan/discord-bot-id/discord-bot-id-env/lib/python3.8/site-packages/aiohttp/connector.py", line 964, in _create_direct_connection
    hosts = await asyncio.shield(self._resolve_host(
  File "/home/hukasan/discord-bot-id/discord-bot-id-env/lib/python3.8/site-packages/aiohttp/connector.py", line 829, in _resolve_host
    addrs = await \
  File "/home/hukasan/discord-bot-id/discord-bot-id-env/lib/python3.8/site-packages/aiohttp/resolver.py", line 29, in resolve
    infos = await self._loop.getaddrinfo(
  File "/usr/lib/python3.8/asyncio/base_events.py", line 817, in getaddrinfo
    return await self.run_in_executor(
  File "/usr/lib/python3.8/concurrent/futures/thread.py", line 57, in run
    result = self.fn(*self.args, **self.kwargs)
  File "/usr/lib/python3.8/socket.py", line 914, in getaddrinfo
    for res in _socket.getaddrinfo(host, port, family, type, proto, flags):
socket.gaierror: [Errno -3] Temporary failure in name resolution

The above exception was the direct cause of the following exception:

Traceback (most recent call last):
  File "/home/hukasan/discord-bot-id/discord-bot-id-env/lib/python3.8/site-packages/discord/client.py", line 499, in connect
    await self._connect()
  File "/home/hukasan/discord-bot-id/discord-bot-id-env/lib/python3.8/site-packages/discord/client.py", line 469, in _connect
    self.ws = await asyncio.wait_for(coro, timeout=180.0)
  File "/usr/lib/python3.8/asyncio/tasks.py", line 483, in wait_for
    return fut.result()
  File "/home/hukasan/discord-bot-id/discord-bot-id-env/lib/python3.8/site-packages/discord/gateway.py", line 224, in from_client
    gateway = await client.http.get_gateway()
  File "/home/hukasan/discord-bot-id/discord-bot-id-env/lib/python3.8/site-packages/discord/http.py", line 827, in get_gateway
    data = await self.request(Route('GET', '/gateway'))
  File "/home/hukasan/discord-bot-id/discord-bot-id-env/lib/python3.8/site-packages/discord/http.py", line 165, in request
    async with self.__session.request(method, url, **kwargs) as r:
  File "/home/hukasan/discord-bot-id/discord-bot-id-env/lib/python3.8/site-packages/aiohttp/client.py", line 1012, in __aenter__
    self._resp = await self._coro
  File "/home/hukasan/discord-bot-id/discord-bot-id-env/lib/python3.8/site-packages/aiohttp/client.py", line 480, in _request
    conn = await self._connector.connect(
  File "/home/hukasan/discord-bot-id/discord-bot-id-env/lib/python3.8/site-packages/aiohttp/connector.py", line 523, in connect
    proto = await self._create_connection(req, traces, timeout)
  File "/home/hukasan/discord-bot-id/discord-bot-id-env/lib/python3.8/site-packages/aiohttp/connector.py", line 858, in _create_connection
    _, proto = await self._create_direct_connection(
  File "/home/hukasan/discord-bot-id/discord-bot-id-env/lib/python3.8/site-packages/aiohttp/connector.py", line 971, in _create_direct_connection
    raise ClientConnectorError(req.connection_key, exc) from exc
aiohttp.client_exceptions.ClientConnectorError: Cannot connect to host discordapp.com:443 ssl:default [Temporary failure in name resolution]